Workbook

Sheet dataset_1
A1: instant | B1: dteday | C1: season | D1: yr | E1: mnth | F1: hr | G1: holiday | H1: weekday | I1: weathersit | J1: temp
A2: 1 | B2: 40544 | C2: 1 | D2: 0 | E2: 1 | F2: 0 | G2: FALSE | H2: 6 | I2: 1 | J2: 0.24
A3: 2 | B3: 40544 | C3: 1 | D3: 0 | E3: 1 | F3: 1 | G3: FALSE | H3: 6 | I3: 1 | J3: 0.22
A4: 3 | B4: 40544 | C4: 1 | D4: 0 | E4: 1 | F4: 2 | G4: FALSE | H4: 6 | I4: 1 | J4: 0.22
A5: 4 | B5: 40544 | C5: 1 | D5: 0 | E5: 1 | F5: 3 | G5: FALSE | H5: 6 | I5: 1 | J5: 0.24
A6: 5 | B6: 40544 | C6: 1 | D6: 0 | E6: 1 | F6: 4 | G6: FALSE | H6: 6 | I6: 1 | J6: 0.24
A7: 6 | B7: 40544 | C7: 1 | D7: 0 | E7: 1 | F7: 5 | G7: FALSE | H7: 6 | I7: 2 | J7: 0.24
A8: 7 | B8: 40544 | C8: 1 | D8: 0 | E8: 1 | F8: 6 | G8: FALSE | H8: 6 | I8: 1 | J8: 0.22
A9: 8 | B9: 40544 | C9: 1 | D9: 0 | E9: 1 | F9: 7 | G9: FALSE | H9: 6 | I9: 1 | J9: 0.2
A10: 9 | B10: 40544 | C10: 1 | D10: 0 | E10: 1 | F10: 8 | G10: FALSE | H10: 6 | I10: 1 | J10: 0.24
A11: 10 | B11: 40544 | C11: 1 | D11: 0 | E11: 1 | F11: 9 | G11: FALSE | H11: 6 | I11: 1 | J11: 0.32
A12: 11 | B12: 40544 | C12: 1 | D12: 0 | E12: 1 | F12: 10 | G12: FALSE | H12: 6 | I12: 1 | J12: 0.38
A13: 12 | B13: 40544 | C13: 1 | D13: 0 | E13: 1 | F13: 11 | G13: FALSE | H13: 6 | I13: 1 | J13: 0.36
... A611: 610 | B611: 40571 | C611: 1 | D611: 0 | E611: 1 | F611: 15 | G611: FALSE | H611: 5 | I611: 2 | J611: 0.2

Sheet dateset_2
A1: instant | B1: atemp | C1: hum | D1: windspeed | E1: casual | F1: registered | G1: cnt | H1: FInal atemp
A2: 1 | B2: 0.2879 | C2: 0.81 | D2: 0 | E2: 3 | F2: 13 | G2: 16 | H2: =IF(ISBLANK(B2),0.197,B2) -> 0.2879
A3: 2 | B3: 0.2727 | C3: 0.8 | D3: 0 | E3: 8 | F3: 32 | G3: 40 | H3: =IF(ISBLANK(B3),0.197,B3) -> 0.2727
A4: 3 | B4: 0.2727 | C4: 0.8 | D4: 0 | E4: 5 | F4: 27 | G4: 32 | H4: =IF(ISBLANK(B4),0.197,B4) -> 0.2727 | J4: Median 0f Atemp | K4: =MEDIAN(B:B) -> 0.197
A5: 4 | B5: 0.2879 | C5: 0.75 | D5: 0 | E5: 3 | F5: 10 | G5: 13 | H5: =IF(ISBLANK(B5),0.197,B5) -> 0.2879
A6: 5 | B6: 0.2879 | C6: 0.75 | D6: 0 | E6: 0 | F6: 1 | G6: 1 | H6: =IF(ISBLANK(B6),0.197,B6) -> 0.2879
A7: 6 | B7: 0.2576 | C7: 0.75 | D7: 0.0896 | E7: 0 | F7: 1 | G7: 1 | H7: =IF(ISBLANK(B7),0.197,B7) -> 0.2576
A8: 7 | B8: 0.2727 | C8: 0.8 | D8: 0 | E8: 2 | F8: 0 | G8: 2 | H8: =IF(ISBLANK(B8),0.197,B8) -> 0.2727
A9: 8 | B9: 0.2576 | C9: 0.86 | D9: 0 | E9: 1 | F9: 2 | G9: 3 | H9: =IF(ISBLANK(B9),0.197,B9) -> 0.2576
A10: 9 | C10: 0.75 | D10: 0 | E10: 1 | F10: 7 | G10: 8 | H10: =IF(ISBLANK(B10),0.197,B10) -> 0.197
A11: 10 | B11: 0.3485 | C11: 0.76 | D11: 0 | E11: 8 | F11: 6 | G11: 14 | H11: =IF(ISBLANK(B11),0.197,B11) -> 0.3485
A12: 11 | B12: 0.3939 | C12: 0.76 | D12: 0.2537 | E12: 12 | F12: 24 | G12: 36 | H12: =IF(ISBLANK(B12),0.197,B12) -> 0.3939
A13: 12 | B13: 0.3333 | C13: 0.81 | D13: 0.2836 | E13: 26 | F13: 30 | G13: 56 | H13: =IF(ISBLANK(B13),0.197,B13) -> 0.3333
A14: 13 | B14: 0.4242 | C14: 0.77 | D14: 0.2836 | E14: 29 | F14: 55 | G14: 84 | H14: =IF(ISBLANK(B14),0.197,B14) -> 0.4242
A15: 14 | B15: 0.4545 | C15: 0.72 | D15: 0.2985 | E15: 47 | F15: 47 | G15: 94 | H15: =IF(ISBLANK(B15),0.197,B15) -> 0.4545
A16: 15 | B16: 0.4545 | C16: 0.72 | D16: 0.2836 | E16: 35 | F16: 71 | G16: 106 | H16: =IF(ISBLANK(B16),0.197,B16) -> 0.4545
A17: 16 | B17: 0.4394 | C17: 0.77 | D17: 0.2985 | E17: 40 | F17: 70 | G17: 110 | H17: =IF(ISBLANK(B17),0.197,B17) -> 0.4394
A18: 17 | B18: 0.4242 | C18: 0.82 | D18: 0.2985 | E18: 41 | F18: 52 | G18: 93 | H18: =IF(ISBLANK(B18),0.197,B18) -> 0.4242
A19: 18 | C19: 0.82 | D19: 0.2836 | E19: 15 | F19: 52 | G19: 67 | H19: =IF(ISBLANK(B19),0.197,B19) -> 0.197
A20: 19 | B20: 0.4242 | C20: 0.88 | D20: 0.2537 | E20: 9 | F20: 26 | G20: 35 | H20: =IF(ISBLANK(B20),0.197,B20) -> 0.4242
A21: 20 | B21: 0.4242 | C21: 0.88 | D21: 0.2537 | E21: 6 | F21: 31 | G21: 37 | H21: =IF(ISBLANK(B21),0.197,B21) -> 0.4242
A22: 21 | B22: 0.4091 | C22: 0.87 | D22: 0.2537 | E22: 11 | F22: 25 | G22: 36 | H22: =IF(ISBLANK(B22),0.197,B22) -> 0.4091
A23: 22 | B23: 0.4091 | C23: 0.87 | D23: 0.194 | E23: 3 | F23: 31 | G23: 34 | H23: =IF(ISBLANK(B23),0.197,B23) -> 0.4091
A24: 23 | B24: 0.4091 | C24: 0.94 | D24: 0.2239 | E24: 11 | F24: 17 | G24: 28 | H24: =IF(ISBLANK(B24),0.197,B24) -> 0.4091
A25: 24 | C25: 0.88 | D25: 0.2985 | E25: 15 | F25: 24 | G25: 39 | H25: =IF(ISBLANK(B25),0.197,B25) -> 0.197
A26: 25 | B26: 0.4545 | C26: 0.88 | D26: 0.2985 | E26: 4 | F26: 13 | G26: 17 | H26: =IF(ISBLANK(B26),0.197,B26) -> 0.4545
A27: 26 | B27: 0.4394 | C27: 0.94 | D27: 0.2537 | E27: 1 | F27: 16 | G27: 17 | H27: =IF(ISBLANK(B27),0.197,B27) -> 0.4394
A28: 27 | B28: 0.4242 | C28: 1 | D28: 0.2836 | E28: 1 | F28: 8 | G28: 9 | H28: =IF(ISBLANK(B28),0.197,B28) -> 0.4242
A29: 28 | B29: 0.4545 | C29: 0.94 | D29: 0.194 | E29: 2 | F29: 4 | G29: 6 | H29: =IF(ISBLANK(B29),0.197,B29) -> 0.4545
A30: 29 | C30: 0.94 | D30: 0.194 | E30: 2 | F30: 1 | G30: 3 | H30: =IF(ISBLANK(B30),0.197,B30) -> 0.197
A31: 30 | B31: 0.4242 | C31: 0.77 | D31: 0.2985 | E31: 0 | F31: 2 | G31: 2 | H31: =IF(ISBLANK(B31),0.197,B31) -> 0.4242
A32: 31 | B32: 0.4091 | C32: 0.76 | D32: 0.194 | E32: 0 | F32: 1 | G32: 1 | H32: =IF(ISBLANK(B32),0.197,B32) -> 0.4091
A33: 32 | B33: 0.4091 | C33: 0.71 | D33: 0.2239 | E33: 0 | F33: 8 | G33: 8 | H33: =IF(ISBLANK(B33),0.197,B33) -> 0.4091
A34: 33 | C34: 0.76 | D34: 0.2239 | E34: 1 | F34: 19 | G34: 20 | H34: =IF(ISBLANK(B34),0.197,B34) -> 0.197
A35: 34 | B35: 0.3485 | C35: 0.81 | D35: 0.2239 | E35: 7 | F35: 46 | G35: 53 | H35: =IF(ISBLANK(B35),0.197,B35) -> 0.3485
A36: 35 | B36: 0.3333 | C36: 0.71 | D36: 0.2537 | E36: 16 | F36: 54 | G36: 70 | H36: =IF(ISBLANK(B36),0.197,B36) -> 0.3333
A37: 36 | B37: 0.3333 | C37: 0.66 | D37: 0.2985 | E37: 20 | F37: 73 | G37: 93 | H37: =IF(ISBLANK(B37),0.197,B37) -> 0.3333
A38: 37 | B38: 0.3485 | C38: 0.66 | D38: 0.1343 | E38: 11 | F38: 64 | G38: 75 | H38: =IF(ISBLANK(B38),0.197,B38) -> 0.3485
A39: 38 | C39: 0.76 | D39: 0.194 | E39: 4 | F39: 55 | G39: 59 | H39: =IF(ISBLANK(B39),0.197,B39) -> 0.197
A40: 39 | B40: 0.3333 | C40: 0.81 | D40: 0.1642 | E40: 19 | F40: 55 | G40: 74 | H40: =IF(ISBLANK(B40),0.197,B40) -> 0.3333
...

Sheet datset_3
A1: instant | B1: dteday | C1: season | D1: yr | E1: mnth | F1: hr | G1: holiday | H1: weekday | I1: weathersit | J1: temp | K1: atemp | L1: hum | M1: windspeed | N1: casual | O1: registered | P1: cnt
A2: 620 | B2: 40572 | C2: 1 | D2: 0 | E2: 1 | F2: 1 | G2: FALSE | H2: 6 | I2: 1 | J2: 0.22 | K2: 0.2273 | L2: 0.64 | M2: 0.194 | N2: 0 | O2: 20 | P2: 20
A3: 621 | B3: 40572 | C3: 1 | D3: 0 | E3: 1 | F3: 2 | G3: FALSE | H3: 6 | I3: 1 | J3: 0.22 | K3: 0.2273 | L3: 0.64 | M3: 0.1642 | N3: 0 | O3: 15 | P3: 15
A4: 622 | B4: 40572 | C4: 1 | D4: 0 | E4: 1 | F4: 3 | G4: FALSE | H4: 6 | I4: 1 | J4: 0.2 | K4: 0.2121 | L4: 0.64 | M4: 0.1343 | N4: 3 | O4: 5 | P4: 8
A5: 623 | B5: 40572 | C5: 1 | D5: 0 | E5: 1 | F5: 4 | G5: FALSE | H5: 6 | I5: 1 | J5: 0.16 | K5: 0.1818 | L5: 0.69 | M5: 0.1045 | N5: 1 | O5: 2 | P5: 3
A6: 624 | B6: 40572 | C6: 1 | D6: 0 | E6: 1 | F6: 6 | G6: FALSE | H6: 6 | I6: 1 | J6: 0.16 | K6: 0.1818 | L6: 0.64 | M6: 0.1343 | N6: 0 | O6: 2 | P6: 2
A7: 625 | B7: 40572 | C7: 1 | D7: 0 | E7: 1 | F7: 7 | G7: FALSE | H7: 6 | I7: 1 | J7: 0.16 | K7: 0.1818 | L7: 0.59 | M7: 0.1045 | N7: 1 | O7: 4 | P7: 5
A8: 626 | B8: 40572 | C8: 1 | D8: 0 | E8: 1 | F8: 8 | G8: FALSE | H8: 6 | I8: 1 | J8: 0.18 | K8: 0.197 | L8: 0.55 | M8: 0.1642 | N8: 3 | O8: 31 | P8: 34
A9: 627 | B9: 40572 | C9: 1 | D9: 0 | E9: 1 | F9: 9 | G9: FALSE | H9: 6 | I9: 1 | J9: 0.18 | K9: 0.2121 | L9: 0.59 | M9: 0.0896 | N9: 0 | O9: 34 | P9: 34
A10: 628 | B10: 40572 | C10: 1 | D10: 0 | E10: 1 | F10: 10 | G10: FALSE | H10: 6 | I10: 2 | J10: 0.18 | K10: 0.2121 | L10: 0.64 | M10: 0.1045 | N10: 4 | O10: 51 | P10: 55
A11: 629 | B11: 40572 | C11: 1 | D11: 0 | E11: 1 | F11: 11 | G11: FALSE | H11: 6 | I11: 2 | J11: 0.18 | K11: 0.197 | L11: 0.64 | M11: 0.1343 | N11: 4 | O11: 60 | P11: 64
A12: 630 | B12: 40572 | C12: 1 | D12: 0 | E12: 1 | F12: 12 | G12: FALSE | H12: 6 | I12: 2 | J12: 0.2 | K12: 0.197 | L12: 0.59 | M12: 0.194 | N12: 12 | O12: 66 | P12: 78
A13: 631 | B13: 40572 | C13: 1 | D13: 0 | E13: 1 | F13: 13 | G13: FALSE | H13: 6 | I13: 2 | J13: 0.22 | K13: 0.2273 | L13: 0.55 | M13: 0.1642 | N13: 9 | O13: 56 | P13: 65
... A391: 619 | B391: 40572 | C391: 1 | D391: 0 | E391: 1 | F391: 0 | G391: FALSE | H391: 6 | I391: 1 | J391: 0.22 | K391: 0.197 | L391: 0.64 | M391: 0.3582 | N391: 2 | O391: 26 | P391: 28

Sheet dataset 1+2
A1: instant | B1: dteday | C1: season | D1: yr | E1: mnth | F1: hr | G1: holiday | H1: weekday | I1: weathersit | J1: temp | K1: instant2 | L1: atemp | M1: hum | N1: windspeed | O1: casual | P1: registered | Q1: cnt
A2: 1 | B2: 40544 | C2: 1 | D2: 0 | E2: 1 | F2: 0 | G2: FALSE | H2: 6 | I2: 1 | J2: 0.24 | K2: 1 | L2: 0.2879 | M2: 0.81 | N2: 0 | O2: 3 | P2: 13 | Q2: 16
A3: 2 | B3: 40544 | C3: 1 | D3: 0 | E3: 1 | F3: 1 | G3: FALSE | H3: 6 | I3: 1 | J3: 0.22 | K3: 2 | L3: 0.2727 | M3: 0.8 | N3: 0 | O3: 8 | P3: 32 | Q3: 40
A4: 3 | B4: 40544 | C4: 1 | D4: 0 | E4: 1 | F4: 2 | G4: FALSE | H4: 6 | I4: 1 | J4: 0.22 | K4: 3 | L4: 0.2727 | M4: 0.8 | N4: 0 | O4: 5 | P4: 27 | Q4: 32
A5: 4 | B5: 40544 | C5: 1 | D5: 0 | E5: 1 | F5: 3 | G5: FALSE | H5: 6 | I5: 1 | J5: 0.24 | K5: 4 | L5: 0.2879 | M5: 0.75 | N5: 0 | O5: 3 | P5: 10 | Q5: 13
A6: 5 | B6: 40544 | C6: 1 | D6: 0 | E6: 1 | F6: 4 | G6: FALSE | H6: 6 | I6: 1 | J6: 0.24 | K6: 5 | L6: 0.2879 | M6: 0.75 | N6: 0 | O6: 0 | P6: 1 | Q6: 1
A7: 6 | B7: 40544 | C7: 1 | D7: 0 | E7: 1 | F7: 5 | G7: FALSE | H7: 6 | I7: 2 | J7: 0.24 | K7: 6 | L7: 0.2576 | M7: 0.75 | N7: 0.0896 | O7: 0 | P7: 1 | Q7: 1
A8: 7 | B8: 40544 | C8: 1 | D8: 0 | E8: 1 | F8: 6 | G8: FALSE | H8: 6 | I8: 1 | J8: 0.22 | K8: 7 | L8: 0.2727 | M8: 0.8 | N8: 0 | O8: 2 | P8: 0 | Q8: 2
A9: 8 | B9: 40544 | C9: 1 | D9: 0 | E9: 1 | F9: 7 | G9: FALSE | H9: 6 | I9: 1 | J9: 0.2 | K9: 8 | L9: 0.2576 | M9: 0.86 | N9: 0 | O9: 1 | P9: 2 | Q9: 3
A10: 9 | B10: 40544 | C10: 1 | D10: 0 | E10: 1 | F10: 8 | G10: FALSE | H10: 6 | I10: 1 | J10: 0.24 | K10: 9 | L10: 0.197 | M10: 0.75 | N10: 0 | O10: 1 | P10: 7 | Q10: 8
A11: 10 | B11: 40544 | C11: 1 | D11: 0 | E11: 1 | F11: 9 | G11: FALSE | H11: 6 | I11: 1 | J11: 0.32 | K11: 10 | L11: 0.3485 | M11: 0.76 | N11: 0 | O11: 8 | P11: 6 | Q11: 14
A12: 11 | B12: 40544 | C12: 1 | D12: 0 | E12: 1 | F12: 10 | G12: FALSE | H12: 6 | I12: 1 | J12: 0.38 | K12: 11 | L12: 0.3939 | M12: 0.76 | N12: 0.2537 | O12: 12 | P12: 24 | Q12: 36
A13: 12 | B13: 40544 | C13: 1 | D13: 0 | E13: 1 | F13: 11 | G13: FALSE | H13: 6 | I13: 1 | J13: 0.36 | K13: 12 | L13: 0.3333 | M13: 0.81 | N13: 0.2836 | O13: 26 | P13: 30 | Q13: 56
... A611: 610 | B611: 40571 | C611: 1 | D611: 0 | E611: 1 | F611: 15 | G611: FALSE | H611: 5 | I611: 2 | J611: 0.2 | K611: 610 | L611: 0.2576 | M611: 0.86 | N611: 0 | O611: 1 | P611: 40 | Q611: 41

Sheet final dataset
A1: instant | B1: dteday | C1: season | D1: yr | E1: mnth | F1: hr | G1: holiday | H1: weekday | I1: weathersit | J1: temp | K1: atemp | L1: hum | M1: windspeed | N1: casual | O1: registered | P1: total count | Q1: Weather sit | R1: Weater situation | S1: Day | T1: Month | U1: Year | V1: Time | W1: Days | X1: Working/Holiday
A2: 1 | B2: 40544 | C2: 1 | D2: 0 | E2: 1 | F2: 0 | G2: FALSE | H2: 6 | I2: 1 | J2: 0.24 | K2: 0.2879 | L2: 0.81 | M2: 0 | N2: 3 | O2: 13 | P2: 16 | Q2: =IF(I2=1,"Clear",IF(I2=2,"Cloudy",IF(I2=3,"Light Rain",IF(I2=4,"Heavy Rain")))) -> Clear | R2: =IF(I2=1,"Normal",IF(I2=2,"Yellow Alert",IF(I2=3,"Orange Alert",IF(I2=4,"Red Alert")))) -> Normal | S2: =DAY(B:B) -> 1 | T2: =MONTH(dataset_1!B:B) -> 1 | U2: =YEAR(B:B) -> 2011 | V2: =TEXT(F2/24,"H AM/PM") -> 12 AM | W2: =IF(H2=6,"Saturday",IF(H2=0,"Sunday",IF(H2=1,"Monday",IF(H2=2,"Tuesday",IF(H2=3,"Wednesday",IF(H2=4,"Thursday",IF(H2=5,"Friday"))))))) -> Saturday | X2: =IF(G2=FALSE,"Working day", IF(G2=TRUE,"Holiday")) -> Working day
A3: 2 | B3: 40544 | C3: 1 | D3: 0 | E3: 1 | F3: 1 | G3: FALSE | H3: 6 | I3: 1 | J3: 0.22 | K3: 0.2727 | L3: 0.8 | M3: 0 | N3: 8 | O3: 32 | P3: 40 | Q3: =IF(I3=1,"Clear",IF(I3=2,"Cloudy",IF(I3=3,"Light Rain",IF(I3=4,"Heavy Rain")))) -> Clear | R3: =IF(I3=1,"Normal",IF(I3=2,"Yellow Alert",IF(I3=3,"Orange Alert",IF(I3=4,"Red Alert")))) -> Normal | S3: =DAY(B:B) -> 1 | T3: =MONTH(dataset_1!B:B) -> 1 | U3: =YEAR(B:B) -> 2011 | V3: =TEXT(F3/24,"H AM/PM") -> 1 AM | W3: =IF(H3=6,"Saturday",IF(H3=0,"Sunday",IF(H3=1,"Monday",IF(H3=2,"Tuesday",IF(H3=3,"Wednesday",IF(H3=4,"Thursday",IF(H3=5,"Friday"))))))) -> Saturday | X3: =IF(G3=FALSE,"Working day", IF(G3=TRUE,"Holiday")) -> Working day
A4: 3 | B4: 40544 | C4: 1 | D4: 0 | E4: 1 | F4: 2 | G4: FALSE | H4: 6 | I4: 1 | J4: 0.22 | K4: 0.2727 | L4: 0.8 | M4: 0 | N4: 5 | O4: 27 | P4: 32 | Q4: =IF(I4=1,"Clear",IF(I4=2,"Cloudy",IF(I4=3,"Light Rain",IF(I4=4,"Heavy Rain")))) -> Clear | R4: =IF(I4=1,"Normal",IF(I4=2,"Yellow Alert",IF(I4=3,"Orange Alert",IF(I4=4,"Red Alert")))) -> Normal | S4: =DAY(B:B) -> 1 | T4: =MONTH(dataset_1!B:B) -> 1 | U4: =YEAR(B:B) -> 2011 | V4: =TEXT(F4/24,"H AM/PM") -> 2 AM | W4: =IF(H4=6,"Saturday",IF(H4=0,"Sunday",IF(H4=1,"Monday",IF(H4=2,"Tuesday",IF(H4=3,"Wednesday",IF(H4=4,"Thursday",IF(H4=5,"Friday"))))))) -> Saturday | X4: =IF(G4=FALSE,"Working day", IF(G4=TRUE,"Holiday")) -> Working day
A5: 4 | B5: 40544 | C5: 1 | D5: 0 | E5: 1 | F5: 3 | G5: FALSE | H5: 6 | I5: 1 | J5: 0.24 | K5: 0.2879 | L5: 0.75 | M5: 0 | N5: 3 | O5: 10 | P5: 13 | Q5: =IF(I5=1,"Clear",IF(I5=2,"Cloudy",IF(I5=3,"Light Rain",IF(I5=4,"Heavy Rain")))) -> Clear | R5: =IF(I5=1,"Normal",IF(I5=2,"Yellow Alert",IF(I5=3,"Orange Alert",IF(I5=4,"Red Alert")))) -> Normal | S5: =DAY(B:B) -> 1 | T5: =MONTH(dataset_1!B:B) -> 1 | U5: =YEAR(B:B) -> 2011 | V5: =TEXT(F5/24,"H AM/PM") -> 3 AM | W5: =IF(H5=6,"Saturday",IF(H5=0,"Sunday",IF(H5=1,"Monday",IF(H5=2,"Tuesday",IF(H5=3,"Wednesday",IF(H5=4,"Thursday",IF(H5=5,"Friday"))))))) -> Saturday | X5: =IF(G5=FALSE,"Working day", IF(G5=TRUE,"Holiday")) -> Working day
A6: 5 | B6: 40544 | C6: 1 | D6: 0 | E6: 1 | F6: 4 | G6: FALSE | H6: 6 | I6: 1 | J6: 0.24 | K6: 0.2879 | L6: 0.75 | M6: 0 | N6: 0 | O6: 1 | P6: 1 | Q6: =IF(I6=1,"Clear",IF(I6=2,"Cloudy",IF(I6=3,"Light Rain",IF(I6=4,"Heavy Rain")))) -> Clear | R6: =IF(I6=1,"Normal",IF(I6=2,"Yellow Alert",IF(I6=3,"Orange Alert",IF(I6=4,"Red Alert")))) -> Normal | S6: =DAY(B:B) -> 1 | T6: =MONTH(dataset_1!B:B) -> 1 | U6: =YEAR(B:B) -> 2011 | V6: =TEXT(F6/24,"H AM/PM") -> 4 AM | W6: =IF(H6=6,"Saturday",IF(H6=0,"Sunday",IF(H6=1,"Monday",IF(H6=2,"Tuesday",IF(H6=3,"Wednesday",IF(H6=4,"Thursday",IF(H6=5,"Friday"))))))) -> Saturday | X6: =IF(G6=FALSE,"Working day", IF(G6=TRUE,"Holiday")) -> Working day
A7: 6 | B7: 40544 | C7: 1 | D7: 0 | E7: 1 | F7: 5 | G7: FALSE | H7: 6 | I7: 2 | J7: 0.24 | K7: 0.2576 | L7: 0.75 | M7: 0.0896 | N7: 0 | O7: 1 | P7: 1 | Q7: =IF(I7=1,"Clear",IF(I7=2,"Cloudy",IF(I7=3,"Light Rain",IF(I7=4,"Heavy Rain")))) -> Cloudy | R7: =IF(I7=1,"Normal",IF(I7=2,"Yellow Alert",IF(I7=3,"Orange Alert",IF(I7=4,"Red Alert")))) -> Yellow Alert | S7: =DAY(B:B) -> 1 | T7: =MONTH(dataset_1!B:B) -> 1 | U7: =YEAR(B:B) -> 2011 | V7: =TEXT(F7/24,"H AM/PM") -> 5 AM | W7: =IF(H7=6,"Saturday",IF(H7=0,"Sunday",IF(H7=1,"Monday",IF(H7=2,"Tuesday",IF(H7=3,"Wednesday",IF(H7=4,"Thursday",IF(H7=5,"Friday"))))))) -> Saturday | X7: =IF(G7=FALSE,"Working day", IF(G7=TRUE,"Holiday")) -> Working day
A8: 7 | B8: 40544 | C8: 1 | D8: 0 | E8: 1 | F8: 6 | G8: FALSE | H8: 6 | I8: 1 | J8: 0.22 | K8: 0.2727 | L8: 0.8 | M8: 0 | N8: 2 | O8: 0 | P8: 2 | Q8: =IF(I8=1,"Clear",IF(I8=2,"Cloudy",IF(I8=3,"Light Rain",IF(I8=4,"Heavy Rain")))) -> Clear | R8: =IF(I8=1,"Normal",IF(I8=2,"Yellow Alert",IF(I8=3,"Orange Alert",IF(I8=4,"Red Alert")))) -> Normal | S8: =DAY(B:B) -> 1 | T8: =MONTH(dataset_1!B:B) -> 1 | U8: =YEAR(B:B) -> 2011 | V8: =TEXT(F8/24,"H AM/PM") -> 6 AM | W8: =IF(H8=6,"Saturday",IF(H8=0,"Sunday",IF(H8=1,"Monday",IF(H8=2,"Tuesday",IF(H8=3,"Wednesday",IF(H8=4,"Thursday",IF(H8=5,"Friday"))))))) -> Saturday | X8: =IF(G8=FALSE,"Working day", IF(G8=TRUE,"Holiday")) -> Working day
A9: 8 | B9: 40544 | C9: 1 | D9: 0 | E9: 1 | F9: 7 | G9: FALSE | H9: 6 | I9: 1 | J9: 0.2 | K9: 0.2576 | L9: 0.86 | M9: 0 | N9: 1 | O9: 2 | P9: 3 | Q9: =IF(I9=1,"Clear",IF(I9=2,"Cloudy",IF(I9=3,"Light Rain",IF(I9=4,"Heavy Rain")))) -> Clear | R9: =IF(I9=1,"Normal",IF(I9=2,"Yellow Alert",IF(I9=3,"Orange Alert",IF(I9=4,"Red Alert")))) -> Normal | S9: =DAY(B:B) -> 1 | T9: =MONTH(dataset_1!B:B) -> 1 | U9: =YEAR(B:B) -> 2011 | V9: =TEXT(F9/24,"H AM/PM") -> 7 AM | W9: =IF(H9=6,"Saturday",IF(H9=0,"Sunday",IF(H9=1,"Monday",IF(H9=2,"Tuesday",IF(H9=3,"Wednesday",IF(H9=4,"Thursday",IF(H9=5,"Friday"))))))) -> Saturday | X9: =IF(G9=FALSE,"Working day", IF(G9=TRUE,"Holiday")) -> Working day
A10: 9 | B10: 40544 | C10: 1 | D10: 0 | E10: 1 | F10: 8 | G10: FALSE | H10: 6 | I10: 1 | J10: 0.24 | K10: 0.197 | L10: 0.75 | M10: 0 | N10: 1 | O10: 7 | P10: 8 | Q10: =IF(I10=1,"Clear",IF(I10=2,"Cloudy",IF(I10=3,"Light Rain",IF(I10=4,"Heavy Rain")))) -> Clear | R10: =IF(I10=1,"Normal",IF(I10=2,"Yellow Alert",IF(I10=3,"Orange Alert",IF(I10=4,"Red Alert")))) -> Normal | S10: =DAY(B:B) -> 1 | T10: =MONTH(dataset_1!B:B) -> 1 | U10: =YEAR(B:B) -> 2011 | V10: =TEXT(F10/24,"H AM/PM") -> 8 AM | W10: =IF(H10=6,"Saturday",IF(H10=0,"Sunday",IF(H10=1,"Monday",IF(H10=2,"Tuesday",IF(H10=3,"Wednesday",IF(H10=4,"Thursday",IF(H10=5,"Friday"))))))) -> Saturday | X10: =IF(G10=FALSE,"Working day", IF(G10=TRUE,"Holiday")) -> Working day
A11: 10 | B11: 40544 | C11: 1 | D11: 0 | E11: 1 | F11: 9 | G11: FALSE | H11: 6 | I11: 1 | J11: 0.32 | K11: 0.3485 | L11: 0.76 | M11: 0 | N11: 8 | O11: 6 | P11: 14 | Q11: =IF(I11=1,"Clear",IF(I11=2,"Cloudy",IF(I11=3,"Light Rain",IF(I11=4,"Heavy Rain")))) -> Clear | R11: =IF(I11=1,"Normal",IF(I11=2,"Yellow Alert",IF(I11=3,"Orange Alert",IF(I11=4,"Red Alert")))) -> Normal | S11: =DAY(B:B) -> 1 | T11: =MONTH(dataset_1!B:B) -> 1 | U11: =YEAR(B:B) -> 2011 | V11: =TEXT(F11/24,"H AM/PM") -> 9 AM | W11: =IF(H11=6,"Saturday",IF(H11=0,"Sunday",IF(H11=1,"Monday",IF(H11=2,"Tuesday",IF(H11=3,"Wednesday",IF(H11=4,"Thursday",IF(H11=5,"Friday"))))))) -> Saturday | X11: =IF(G11=FALSE,"Working day", IF(G11=TRUE,"Holiday")) -> Working day
A12: 11 | B12: 40544 | C12: 1 | D12: 0 | E12: 1 | F12: 10 | G12: FALSE | H12: 6 | I12: 1 | J12: 0.38 | K12: 0.3939 | L12: 0.76 | M12: 0.2537 | N12: 12 | O12: 24 | P12: 36 | Q12: =IF(I12=1,"Clear",IF(I12=2,"Cloudy",IF(I12=3,"Light Rain",IF(I12=4,"Heavy Rain")))) -> Clear | R12: =IF(I12=1,"Normal",IF(I12=2,"Yellow Alert",IF(I12=3,"Orange Alert",IF(I12=4,"Red Alert")))) -> Normal | S12: =DAY(B:B) -> 1 | T12: =MONTH(dataset_1!B:B) -> 1 | U12: =YEAR(B:B) -> 2011 | V12: =TEXT(F12/24,"H AM/PM") -> 10 AM | W12: =IF(H12=6,"Saturday",IF(H12=0,"Sunday",IF(H12=1,"Monday",IF(H12=2,"Tuesday",IF(H12=3,"Wednesday",IF(H12=4,"Thursday",IF(H12=5,"Friday"))))))) -> Saturday | X12: =IF(G12=FALSE,"Working day", IF(G12=TRUE,"Holiday")) -> Working day
A13: 12 | B13: 40544 | C13: S | D13: 0 | E13: 1 | F13: 11 | G13: FALSE | H13: 6 | I13: 1 | J13: 0.36 | K13: 0.3333 | L13: 0.81 | M13: 0.2836 | N13: 26 | O13: 30 | P13: 56 | Q13: =IF(I13=1,"Clear",IF(I13=2,"Cloudy",IF(I13=3,"Light Rain",IF(I13=4,"Heavy Rain")))) -> Clear | R13: =IF(I13=1,"Normal",IF(I13=2,"Yellow Alert",IF(I13=3,"Orange Alert",IF(I13=4,"Red Alert")))) -> Normal | S13: =DAY(B:B) -> 1 | T13: =MONTH(dataset_1!B:B) -> 1 | U13: =YEAR(B:B) -> 2011 | V13: =TEXT(F13/24,"H AM/PM") -> 11 AM | W13: =IF(H13=6,"Saturday",IF(H13=0,"Sunday",IF(H13=1,"Monday",IF(H13=2,"Tuesday",IF(H13=3,"Wednesday",IF(H13=4,"Thursday",IF(H13=5,"Friday"))))))) -> Saturday | X13: =IF(G13=FALSE,"Working day", IF(G13=TRUE,"Holiday")) -> Working day
A14: 13 | B14: 40544 | C14: 1 | D14: 0 | E14: 1 | F14: 12 | G14: FALSE | H14: 6 | I14: 1 | J14: 0.42 | K14: 0.4242 | L14: 0.77 | M14: 0.2836 | N14: 29 | O14: 55 | P14: 84 | Q14: =IF(I14=1,"Clear",IF(I14=2,"Cloudy",IF(I14=3,"Light Rain",IF(I14=4,"Heavy Rain")))) -> Clear | R14: =IF(I14=1,"Normal",IF(I14=2,"Yellow Alert",IF(I14=3,"Orange Alert",IF(I14=4,"Red Alert")))) -> Normal | S14: =DAY(B:B) -> 1 | T14: =MONTH(dataset_1!B:B) -> 1 | U14: =YEAR(B:B) -> 2011 | V14: =TEXT(F14/24,"H AM/PM") -> 12 PM | W14: =IF(H14=6,"Saturday",IF(H14=0,"Sunday",IF(H14=1,"Monday",IF(H14=2,"Tuesday",IF(H14=3,"Wednesday",IF(H14=4,"Thursday",IF(H14=5,"Friday"))))))) -> Saturday | X14: =IF(G14=FALSE,"Working day", IF(G14=TRUE,"Holiday")) -> Working day
A15: 14 | B15: 40544 | C15: 1 | D15: 0 | E15: 1 | F15: 13 | G15: FALSE | H15: 6 | I15: 2 | J15: 0.46 | K15: 0.4545 | L15: 0.72 | M15: 0.2985 | N15: 47 | O15: 47 | P15: 94 | Q15: =IF(I15=1,"Clear",IF(I15=2,"Cloudy",IF(I15=3,"Light Rain",IF(I15=4,"Heavy Rain")))) -> Cloudy | R15: =IF(I15=1,"Normal",IF(I15=2,"Yellow Alert",IF(I15=3,"Orange Alert",IF(I15=4,"Red Alert")))) -> Yellow Alert | S15: =DAY(B:B) -> 1 | T15: =MONTH(dataset_1!B:B) -> 1 | U15: =YEAR(B:B) -> 2011 | V15: =TEXT(F15/24,"H AM/PM") -> 1 PM | W15: =IF(H15=6,"Saturday",IF(H15=0,"Sunday",IF(H15=1,"Monday",IF(H15=2,"Tuesday",IF(H15=3,"Wednesday",IF(H15=4,"Thursday",IF(H15=5,"Friday"))))))) -> Saturday | X15: =IF(G15=FALSE,"Working day", IF(G15=TRUE,"Holiday")) -> Working day
A16: 15 | B16: 40544 | C16: 1 | D16: 0 | E16: 1 | F16: 14 | G16: FALSE | H16: 6 | I16: 2 | J16: 0.46 | K16: 0.4545 | L16: 0.72 | M16: 0.2836 | N16: 35 | O16: 71 | P16: 106 | Q16: =IF(I16=1,"Clear",IF(I16=2,"Cloudy",IF(I16=3,"Light Rain",IF(I16=4,"Heavy Rain")))) -> Cloudy | R16: =IF(I16=1,"Normal",IF(I16=2,"Yellow Alert",IF(I16=3,"Orange Alert",IF(I16=4,"Red Alert")))) -> Yellow Alert | S16: =DAY(B:B) -> 1 | T16: =MONTH(dataset_1!B:B) -> 1 | U16: =YEAR(B:B) -> 2011 | V16: =TEXT(F16/24,"H AM/PM") -> 2 PM | W16: =IF(H16=6,"Saturday",IF(H16=0,"Sunday",IF(H16=1,"Monday",IF(H16=2,"Tuesday",IF(H16=3,"Wednesday",IF(H16=4,"Thursday",IF(H16=5,"Friday"))))))) -> Saturday | X16: =IF(G16=FALSE,"Working day", IF(G16=TRUE,"Holiday")) -> Working day
A17: 16 | B17: 40544 | C17: 1 | D17: 0 | E17: 1 | F17: 15 | G17: FALSE | H17: 6 | I17: 2 | J17: 0.44 | K17: 0.4394 | L17: 0.77 | M17: 0.2985 | N17: 40 | O17: 70 | P17: 110 | Q17: =IF(I17=1,"Clear",IF(I17=2,"Cloudy",IF(I17=3,"Light Rain",IF(I17=4,"Heavy Rain")))) -> Cloudy | R17: =IF(I17=1,"Normal",IF(I17=2,"Yellow Alert",IF(I17=3,"Orange Alert",IF(I17=4,"Red Alert")))) -> Yellow Alert | S17: =DAY(B:B) -> 1 | T17: =MONTH(dataset_1!B:B) -> 1 | U17: =YEAR(B:B) -> 2011 | V17: =TEXT(F17/24,"H AM/PM") -> 3 PM | W17: =IF(H17=6,"Saturday",IF(H17=0,"Sunday",IF(H17=1,"Monday",IF(H17=2,"Tuesday",IF(H17=3,"Wednesday",IF(H17=4,"Thursday",IF(H17=5,"Friday"))))))) -> Saturday | X17: =IF(G17=FALSE,"Working day", IF(G17=TRUE,"Holiday")) -> Working day
A18: 17 | B18: 40544 | C18: 1 | D18: 0 | E18: 1 | F18: 16 | G18: FALSE | H18: 6 | I18: 2 | J18: 0.42 | K18: 0.4242 | L18: 0.82 | M18: 0.2985 | N18: 41 | O18: 52 | P18: 93 | Q18: =IF(I18=1,"Clear",IF(I18=2,"Cloudy",IF(I18=3,"Light Rain",IF(I18=4,"Heavy Rain")))) -> Cloudy | R18: =IF(I18=1,"Normal",IF(I18=2,"Yellow Alert",IF(I18=3,"Orange Alert",IF(I18=4,"Red Alert")))) -> Yellow Alert | S18: =DAY(B:B) -> 1 | T18: =MONTH(dataset_1!B:B) -> 1 | U18: =YEAR(B:B) -> 2011 | V18: =TEXT(F18/24,"H AM/PM") -> 4 PM | W18: =IF(H18=6,"Saturday",IF(H18=0,"Sunday",IF(H18=1,"Monday",IF(H18=2,"Tuesday",IF(H18=3,"Wednesday",IF(H18=4,"Thursday",IF(H18=5,"Friday"))))))) -> Saturday | X18: =IF(G18=FALSE,"Working day", IF(G18=TRUE,"Holiday")) -> Working day
A19: 18 | B19: 40544 | C19: 1 | D19: 0 | E19: 1 | F19: 17 | G19: FALSE | H19: 6 | I19: 2 | J19: 0.44 | K19: 0.197 | L19: 0.82 | M19: 0.2836 | N19: 15 | O19: 52 | P19: 67 | Q19: =IF(I19=1,"Clear",IF(I19=2,"Cloudy",IF(I19=3,"Light Rain",IF(I19=4,"Heavy Rain")))) -> Cloudy | R19: =IF(I19=1,"Normal",IF(I19=2,"Yellow Alert",IF(I19=3,"Orange Alert",IF(I19=4,"Red Alert")))) -> Yellow Alert | S19: =DAY(B:B) -> 1 | T19: =MONTH(dataset_1!B:B) -> 1 | U19: =YEAR(B:B) -> 2011 | V19: =TEXT(F19/24,"H AM/PM") -> 5 PM | W19: =IF(H19=6,"Saturday",IF(H19=0,"Sunday",IF(H19=1,"Monday",IF(H19=2,"Tuesday",IF(H19=3,"Wednesday",IF(H19=4,"Thursday",IF(H19=5,"Friday"))))))) -> Saturday | X19: =IF(G19=FALSE,"Working day", IF(G19=TRUE,"Holiday")) -> Working day
A20: 19 | B20: 40544 | C20: 1 | D20: 0 | E20: 1 | F20: 18 | G20: FALSE | H20: 6 | I20: 3 | J20: 0.42 | K20: 0.4242 | L20: 0.88 | M20: 0.2537 | N20: 9 | O20: 26 | P20: 35 | Q20: =IF(I20=1,"Clear",IF(I20=2,"Cloudy",IF(I20=3,"Light Rain",IF(I20=4,"Heavy Rain")))) -> Light Rain | R20: =IF(I20=1,"Normal",IF(I20=2,"Yellow Alert",IF(I20=3,"Orange Alert",IF(I20=4,"Red Alert")))) -> Orange Alert | S20: =DAY(B:B) -> 1 | T20: =MONTH(dataset_1!B:B) -> 1 | U20: =YEAR(B:B) -> 2011 | V20: =TEXT(F20/24,"H AM/PM") -> 6 PM | W20: =IF(H20=6,"Saturday",IF(H20=0,"Sunday",IF(H20=1,"Monday",IF(H20=2,"Tuesday",IF(H20=3,"Wednesday",IF(H20=4,"Thursday",IF(H20=5,"Friday"))))))) -> Saturday | X20: =IF(G20=FALSE,"Working day", IF(G20=TRUE,"Holiday")) -> Working day
A21: 20 | B21: 40544 | C21: 1 | D21: 0 | E21: 1 | F21: 19 | G21: FALSE | H21: 6 | I21: 3 | J21: 0.42 | K21: 0.4242 | L21: 0.88 | M21: 0.2537 | N21: 6 | O21: 31 | P21: 37 | Q21: =IF(I21=1,"Clear",IF(I21=2,"Cloudy",IF(I21=3,"Light Rain",IF(I21=4,"Heavy Rain")))) -> Light Rain | R21: =IF(I21=1,"Normal",IF(I21=2,"Yellow Alert",IF(I21=3,"Orange Alert",IF(I21=4,"Red Alert")))) -> Orange Alert | S21: =DAY(B:B) -> 1 | T21: =MONTH(dataset_1!B:B) -> 1 | U21: =YEAR(B:B) -> 2011 | V21: =TEXT(F21/24,"H AM/PM") -> 7 PM | W21: =IF(H21=6,"Saturday",IF(H21=0,"Sunday",IF(H21=1,"Monday",IF(H21=2,"Tuesday",IF(H21=3,"Wednesday",IF(H21=4,"Thursday",IF(H21=5,"Friday"))))))) -> Saturday | X21: =IF(G21=FALSE,"Working day", IF(G21=TRUE,"Holiday")) -> Working day
A22: 21 | B22: 40544 | C22: 1 | D22: 0 | E22: 1 | F22: 20 | G22: FALSE | H22: 6 | I22: 2 | J22: 0.4 | K22: 0.4091 | L22: 0.87 | M22: 0.2537 | N22: 11 | O22: 25 | P22: 36 | Q22: =IF(I22=1,"Clear",IF(I22=2,"Cloudy",IF(I22=3,"Light Rain",IF(I22=4,"Heavy Rain")))) -> Cloudy | R22: =IF(I22=1,"Normal",IF(I22=2,"Yellow Alert",IF(I22=3,"Orange Alert",IF(I22=4,"Red Alert")))) -> Yellow Alert | S22: =DAY(B:B) -> 1 | T22: =MONTH(dataset_1!B:B) -> 1 | U22: =YEAR(B:B) -> 2011 | V22: =TEXT(F22/24,"H AM/PM") -> 8 PM | W22: =IF(H22=6,"Saturday",IF(H22=0,"Sunday",IF(H22=1,"Monday",IF(H22=2,"Tuesday",IF(H22=3,"Wednesday",IF(H22=4,"Thursday",IF(H22=5,"Friday"))))))) -> Saturday | X22: =IF(G22=FALSE,"Working day", IF(G22=TRUE,"Holiday")) -> Working day
A23: 22 | B23: 40544 | C23: 1 | D23: 0 | E23: 1 | F23: 21 | G23: FALSE | H23: 6 | I23: 2 | J23: 0.4 | K23: 0.4091 | L23: 0.87 | M23: 0.194 | N23: 3 | O23: 31 | P23: 34 | Q23: =IF(I23=1,"Clear",IF(I23=2,"Cloudy",IF(I23=3,"Light Rain",IF(I23=4,"Heavy Rain")))) -> Cloudy | R23: =IF(I23=1,"Normal",IF(I23=2,"Yellow Alert",IF(I23=3,"Orange Alert",IF(I23=4,"Red Alert")))) -> Yellow Alert | S23: =DAY(B:B) -> 1 | T23: =MONTH(dataset_1!B:B) -> 1 | U23: =YEAR(B:B) -> 2011 | V23: =TEXT(F23/24,"H AM/PM") -> 9 PM | W23: =IF(H23=6,"Saturday",IF(H23=0,"Sunday",IF(H23=1,"Monday",IF(H23=2,"Tuesday",IF(H23=3,"Wednesday",IF(H23=4,"Thursday",IF(H23=5,"Friday"))))))) -> Saturday | X23: =IF(G23=FALSE,"Working day", IF(G23=TRUE,"Holiday")) -> Working day
A24: 23 | B24: 40544 | C24: 1 | D24: 0 | E24: 1 | F24: 22 | G24: FALSE | H24: 6 | I24: 2 | J24: 0.4 | K24: 0.4091 | L24: 0.94 | M24: 0.2239 | N24: 11 | O24: 17 | P24: 28 | Q24: =IF(I24=1,"Clear",IF(I24=2,"Cloudy",IF(I24=3,"Light Rain",IF(I24=4,"Heavy Rain")))) -> Cloudy | R24: =IF(I24=1,"Normal",IF(I24=2,"Yellow Alert",IF(I24=3,"Orange Alert",IF(I24=4,"Red Alert")))) -> Yellow Alert | S24: =DAY(B:B) -> 1 | T24: =MONTH(dataset_1!B:B) -> 1 | U24: =YEAR(B:B) -> 2011 | V24: =TEXT(F24/24,"H AM/PM") -> 10 PM | W24: =IF(H24=6,"Saturday",IF(H24=0,"Sunday",IF(H24=1,"Monday",IF(H24=2,"Tuesday",IF(H24=3,"Wednesday",IF(H24=4,"Thursday",IF(H24=5,"Friday"))))))) -> Saturday | X24: =IF(G24=FALSE,"Working day", IF(G24=TRUE,"Holiday")) -> Working day
A25: 24 | B25: 40544 | C25: 1 | D25: 0 | E25: 1 | F25: 23 | G25: FALSE | H25: 6 | I25: 2 | J25: 0.46 | K25: 0.197 | L25: 0.88 | M25: 0.2985 | N25: 15 | O25: 24 | P25: 39 | Q25: =IF(I25=1,"Clear",IF(I25=2,"Cloudy",IF(I25=3,"Light Rain",IF(I25=4,"Heavy Rain")))) -> Cloudy | R25: =IF(I25=1,"Normal",IF(I25=2,"Yellow Alert",IF(I25=3,"Orange Alert",IF(I25=4,"Red Alert")))) -> Yellow Alert | S25: =DAY(B:B) -> 1 | T25: =MONTH(dataset_1!B:B) -> 1 | U25: =YEAR(B:B) -> 2011 | V25: =TEXT(F25/24,"H AM/PM") -> 11 PM | W25: =IF(H25=6,"Saturday",IF(H25=0,"Sunday",IF(H25=1,"Monday",IF(H25=2,"Tuesday",IF(H25=3,"Wednesday",IF(H25=4,"Thursday",IF(H25=5,"Friday"))))))) -> Saturday | X25: =IF(G25=FALSE,"Working day", IF(G25=TRUE,"Holiday")) -> Working day
... A1001: 1000 | B1001: 40588 | C1001: 1 | D1001: 0 | E1001: 2 | F1001: 7 | G1001: FALSE | H1001: 1 | I1001: 1 | J1001: 0.34 | K1001: 0.303 | L1001: 0.46 | M1001: 0.2985 | N1001: 2 | O1001: 96 | P1001: 98 | Q1001: =IF(I1001=1,"Clear",IF(I1001=2,"Cloudy",IF(I1001=3,"Light Rain",IF(I1001=4,"Heavy Rain")))) -> Clear | R1001: =IF(I1001=1,"Normal",IF(I1001=2,"Yellow Alert",IF(I1001=3,"Orange Alert",IF(I1001=4,"Red Alert")))) -> Normal | S1001: =DAY(B:B) -> 14 | T1001: =MONTH(dataset_1!B:B) -> 1 | U1001: =YEAR(B:B) -> 2011 | V1001: =TEXT(F1001/24,"H AM/PM") -> 7 AM | W1001: =IF(H1001=6,"Saturday",IF(H1001=0,"Sunday",IF(H1001=1,"Monday",IF(H1001=2,"Tuesday",IF(H1001=3,"Wednesday",IF(H1001=4,"Thursday",IF(H1001=5,"Friday"))))))) -> Monday | X1001: =IF(G1001=FALSE,"Working day", IF(G1001=TRUE,"Holiday")) -> Working day

Sheet Rider analysis
A3: Bike Rental Insights & Summary
D7: Column1 | E7: Column2
D8: Total Riders | E8: =SUM('final dataset'!P:P) -> 58304
D9: Average Riders per records | E9: =AVERAGE('final dataset'!P:P) -> 58.304
D10: Record riders per record | E10: =COUNT('final dataset'!P:P) -> 1000
D11: Highest Rider Count | E11: =MAX('final dataset'!P:P) -> 249

Sheet Weater impact on rentals
A2: Impact of Weather on Bike Rentals
D5: Weather situation | E5: Total count
D6: Clear | E6: =SUMIF('final dataset'!R:R,"Normal",'final dataset'!P:P) -> 37373
D7: Cloudy | E7: =SUMIF('final dataset'!R:R,"Orange Alert",'final dataset'!P:P) -> 2789
D8: Light Rain | E8: =SUMIF('final dataset'!R:R,"Yellow Alert",'final dataset'!P:P) -> 18106
D9: Heavy Rain | E9: =SUMIF('final dataset'!R:R,"Red Alert",'final dataset'!P:P) -> 36

Sheet Ridership by day
A2: Days | B2: Sum of casual riders | C2: Sum of registered riders | D2: Sum of total riders
A3: Saturday | B3: 1225 | C3: 6523 | D3: 7748
A4: Sunday | B4: 1477 | C4: 6644 | D4: 8121
A5: Monday | B5: 534 | C5: 7916 | D5: 8450
A6: Tuesday | B6: 457 | C6: 7926 | D6: 8383
A7: Wednesday | B7: 344 | C7: 7705 | D7: 8049
A8: Thursday | B8: 332 | C8: 8126 | D8: 8458
A9: Friday | B9: 552 | C9: 8543 | D9: 9095

Sheet Reg Vs Casual riders
A1: Column1 | B1: Column2
A2: Sum of Registered | B2: =SUM('final dataset'!O:O) -> 53383 | G2: Column1 | H2: Column2
A3: Sum of casual | B3: =SUM('final dataset'!N:N) -> 4921 | G3: Average of registered | H3: =AVERAGE('final dataset'!O:O) -> 53.383
G4: Average of casual | H4: =AVERAGE('final dataset'!N:N) -> 4.921
